Workbook

Sheet الملخص
A1: ملخص اختبارات مدرك
A3: المجال | B3: عدد الاختبارات | C3: ✅ نجح | D3: ❌ فشل | E3: ⚠️ ملاحظة | F3: ☐ لم يُختبر | G3: نسبة النجاح
A4: 1. التشغيل | B4: =COUNTIF(الاختبارات!$B$2:$B$56,A4) -> 7 | C4: =COUNTIFS(الاختبارات!$B$2:$B$56,A4,الاختبارات!$H$2:$H$56,"✅ نجح") -> 7 | D4: =COUNTIFS(الاختبارات!$B$2:$B$56,A4,الاختبارات!$H$2:$H$56,"❌ فشل") -> 0 | E4: =COUNTIFS(الاختبارات!$B$2:$B$56,A4,الاختبارات!$H$2:$H$56,"⚠️ ملاحظة") -> 0 | F4: =COUNTIFS(الاختبارات!$B$2:$B$56,A4,الاختبارات!$H$2:$H$56,"☐ لم يُختبر") -> 0 | G4: =IF(B4=0,0,C4/B4) -> 1
A5: 2. التنظيف | B5: =COUNTIF(الاختبارات!$B$2:$B$56,A5) -> 6 | C5: =COUNTIFS(الاختبارات!$B$2:$B$56,A5,الاختبارات!$H$2:$H$56,"✅ نجح") -> 6 | D5: =COUNTIFS(الاختبارات!$B$2:$B$56,A5,الاختبارات!$H$2:$H$56,"❌ فشل") -> 0 | E5: =COUNTIFS(الاختبارات!$B$2:$B$56,A5,الاختبارات!$H$2:$H$56,"⚠️ ملاحظة") -> 0 | F5: =COUNTIFS(الاختبارات!$B$2:$B$56,A5,الاختبارات!$H$2:$H$56,"☐ لم يُختبر") -> 0 | G5: =IF(B5=0,0,C5/B5) -> 1
A6: 3. السكان | B6: =COUNTIF(الاختبارات!$B$2:$B$56,A6) -> 4 | C6: =COUNTIFS(الاختبارات!$B$2:$B$56,A6,الاختبارات!$H$2:$H$56,"✅ نجح") -> 4 | D6: =COUNTIFS(الاختبارات!$B$2:$B$56,A6,الاختبارات!$H$2:$H$56,"❌ فشل") -> 0 | E6: =COUNTIFS(الاختبارات!$B$2:$B$56,A6,الاختبارات!$H$2:$H$56,"⚠️ ملاحظة") -> 0 | F6: =COUNTIFS(الاختبارات!$B$2:$B$56,A6,الاختبارات!$H$2:$H$56,"☐ لم يُختبر") -> 0 | G6: =IF(B6=0,0,C6/B6) -> 1
A7: 4. الحساب | B7: =COUNTIF(الاختبارات!$B$2:$B$56,A7) -> 6 | C7: =COUNTIFS(الاختبارات!$B$2:$B$56,A7,الاختبارات!$H$2:$H$56,"✅ نجح") -> 6 | D7: =COUNTIFS(الاختبارات!$B$2:$B$56,A7,الاختبارات!$H$2:$H$56,"❌ فشل") -> 0 | E7: =COUNTIFS(الاختبارات!$B$2:$B$56,A7,الاختبارات!$H$2:$H$56,"⚠️ ملاحظة") -> 0 | F7: =COUNTIFS(الاختبارات!$B$2:$B$56,A7,الاختبارات!$H$2:$H$56,"☐ لم يُختبر") -> 0 | G7: =IF(B7=0,0,C7/B7) -> 1
A8: 5. مصفوفة القرار | B8: =COUNTIF(الاختبارات!$B$2:$B$56,A8) -> 5 | C8: =COUNTIFS(الاختبارات!$B$2:$B$56,A8,الاختبارات!$H$2:$H$56,"✅ نجح") -> 5 | D8: =COUNTIFS(الاختبارات!$B$2:$B$56,A8,الاختبارات!$H$2:$H$56,"❌ فشل") -> 0 | E8: =COUNTIFS(الاختبارات!$B$2:$B$56,A8,الاختبارات!$H$2:$H$56,"⚠️ ملاحظة") -> 0 | F8: =COUNTIFS(الاختبارات!$B$2:$B$56,A8,الاختبارات!$H$2:$H$56,"☐ لم يُختبر") -> 0 | G8: =IF(B8=0,0,C8/B8) -> 1
A9: 6. عدسة الطلب | B9: =COUNTIF(الاختبارات!$B$2:$B$56,A9) -> 4 | C9: =COUNTIFS(الاختبارات!$B$2:$B$56,A9,الاختبارات!$H$2:$H$56,"✅ نجح") -> 4 | D9: =COUNTIFS(الاختبارات!$B$2:$B$56,A9,الاختبارات!$H$2:$H$56,"❌ فشل") -> 0 | E9: =COUNTIFS(الاختبارات!$B$2:$B$56,A9,الاختبارات!$H$2:$H$56,"⚠️ ملاحظة") -> 0 | F9: =COUNTIFS(الاختبارات!$B$2:$B$56,A9,الاختبارات!$H$2:$H$56,"☐ لم يُختبر") -> 0 | G9: =IF(B9=0,0,C9/B9) -> 1
A10: 7. فجوة 2030 | B10: =COUNTIF(الاختبارات!$B$2:$B$56,A10) -> 3 | C10: =COUNTIFS(الاختبارات!$B$2:$B$56,A10,الاختبارات!$H$2:$H$56,"✅ نجح") -> 3 | D10: =COUNTIFS(الاختبارات!$B$2:$B$56,A10,الاختبارات!$H$2:$H$56,"❌ فشل") -> 0 | E10: =COUNTIFS(الاختبارات!$B$2:$B$56,A10,الاختبارات!$H$2:$H$56,"⚠️ ملاحظة") -> 0 | F10: =COUNTIFS(الاختبارات!$B$2:$B$56,A10,الاختبارات!$H$2:$H$56,"☐ لم يُختبر") -> 0 | G10: =IF(B10=0,0,C10/B10) -> 1
A11: 8. التقرير | B11: =COUNTIF(الاختبارات!$B$2:$B$56,A11) -> 8 | C11: =COUNTIFS(الاختبارات!$B$2:$B$56,A11,الاختبارات!$H$2:$H$56,"✅ نجح") -> 8 | D11: =COUNTIFS(الاختبارات!$B$2:$B$56,A11,الاختبارات!$H$2:$H$56,"❌ فشل") -> 0 | E11: =COUNTIFS(الاختبارات!$B$2:$B$56,A11,الاختبارات!$H$2:$H$56,"⚠️ ملاحظة") -> 0 | F11: =COUNTIFS(الاختبارات!$B$2:$B$56,A11,الاختبارات!$H$2:$H$56,"☐ لم يُختبر") -> 0 | G11: =IF(B11=0,0,C11/B11) -> 1
A12: 9. الوكيل | B12: =COUNTIF(الاختبارات!$B$2:$B$56,A12) -> 7 | C12: =COUNTIFS(الاختبارات!$B$2:$B$56,A12,الاختبارات!$H$2:$H$56,"✅ نجح") -> 7 | D12: =COUNTIFS(الاختبارات!$B$2:$B$56,A12,الاختبارات!$H$2:$H$56,"❌ فشل") -> 0 | E12: =COUNTIFS(الاختبارات!$B$2:$B$56,A12,الاختبارات!$H$2:$H$56,"⚠️ ملاحظة") -> 0 | F12: =COUNTIFS(الاختبارات!$B$2:$B$56,A12,الاختبارات!$H$2:$H$56,"☐ لم يُختبر") -> 0 | G12: =IF(B12=0,0,C12/B12) -> 1
A13: 10. التوثيق | B13: =COUNTIF(الاختبارات!$B$2:$B$56,A13) -> 3 | C13: =COUNTIFS(الاختبارات!$B$2:$B$56,A13,الاختبارات!$H$2:$H$56,"✅ نجح") -> 3 | D13: =COUNTIFS(الاختبارات!$B$2:$B$56,A13,الاختبارات!$H$2:$H$56,"❌ فشل") -> 0 | E13: =COUNTIFS(الاختبارات!$B$2:$B$56,A13,الاختبارات!$H$2:$H$56,"⚠️ ملاحظة") -> 0 | F13: =COUNTIFS(الاختبارات!$B$2:$B$56,A13,الاختبارات!$H$2:$H$56,"☐ لم يُختبر") -> 0 | G13: =IF(B13=0,0,C13/B13) -> 1
A14: 11. التسليم | B14: =COUNTIF(الاختبارات!$B$2:$B$56,A14) -> 2 | C14: =COUNTIFS(الاختبارات!$B$2:$B$56,A14,الاختبارات!$H$2:$H$56,"✅ نجح") -> 2 | D14: =COUNTIFS(الاختبارات!$B$2:$B$56,A14,الاختبارات!$H$2:$H$56,"❌ فشل") -> 0 | E14: =COUNTIFS(الاختبارات!$B$2:$B$56,A14,الاختبارات!$H$2:$H$56,"⚠️ ملاحظة") -> 0 | F14: =COUNTIFS(الاختبارات!$B$2:$B$56,A14,الاختبارات!$H$2:$H$56,"☐ لم يُختبر") -> 0 | G14: =IF(B14=0,0,C14/B14) -> 1
A15: الإجمالي | B15: =SUM(B4:B14) -> 55 | C15: =SUM(C4:C14) -> 55 | D15: =SUM(D4:D14) -> 0 | E15: =SUM(E4:E14) -> 0 | F15: =SUM(F4:F14) -> 0 | G15: =IF(B15=0,0,C15/B15) -> 1
A17: كيف تستخدمينها:
A18: 1) في ورقة «الاختبارات» نفّذي الخطوات، واكتبي ما ظهر لك في «النتيجة الفعلية»، واختاري الحالة من القائمة.
A19: 2) إذا اختلفت النتيجة عن المتوقع: اختاري «❌ فشل» وصوّري الشاشة وأرسليها لـClaude.
A20: 3) الأرقام المتوقعة أُخذت من آخر تشغيل كامل (22 أكتوبر 2026) ومن الملفات نفسها.
A21: 4) اختبارا «تغيير قرار بشري» و«إرجاع القرار» يجب أن يُنفّذا معاً حتى تعود النتائج الأصلية.

Sheet الاختبارات
A1: # | B1: المجال | C1: الاختبار | D1: الخطوات | E1: النتيجة المتوقعة | F1: وين | G1: النتيجة الفعلية (اكتبيها) | H1: الحالة | I1: ملاحظات
A2: =COUNTIF($B$2:B2,B2) -> 1 | B2: 1. التشغيل | C2: الخطوة الأولى تتوقف للموافقة | D2: من مجلد mudrik شغّلي: python scripts/run_pipeline.py | E2: أربع خطوات تنظيف OK، ثم قائمة القرارات، ثم سطر STOPPED for human review | F2: شاشة cmd | G2: أربع خطوات OK ثم STOPPED for human review (أُعيد 26 أكتوبر بعد حذف الكفاءة والوقف، وفي Colab) | H2: ✅ نجح
A3: =COUNTIF($B$2:B3,B3) -> 2 | B3: 1. التشغيل | C3: الخطوة الثانية تكمل بعد الموافقة | D3: شغّلي: python scripts/run_pipeline.py --yes | E3: كل الخطوات OK، وفي النهاية: RESULT cells: 130 | priority support: 12 | adequate: 81 | high coverage: 37 | F3: شاشة cmd | G3: كل الخطوات OK و RESULT 130 | 12 | 81 | 37 | H3: ✅ نجح
A4: =COUNTIF($B$2:B4,B4) -> 3 | B4: 1. التشغيل | C4: سجل التشغيل كامل | D4: افتحي outputs/pipeline_log.csv | E4: كل الخطوات حالتها ok ولا يوجد FAILED (7 خطوات: 4 تنظيف + 3 تحليل) | F4: outputs/pipeline_log.csv | G4: 7 خطوات ok في pipeline_log.csv (26 أكتوبر) | H4: ✅ نجح
A5: =COUNTIF($B$2:B5,B5) -> 4 | B5: 1. التشغيل | C5: التفاصيل العربية محفوظة | D5: افتحي outputs/pipeline_details.log في Notepad | E5: نص عربي سليم غير مقلوب: «4451 ← 4451»، «32,175,224»… | F5: outputs/pipeline_details.log | G5: العربي سليم في VS Code، وكل الخطوات ok | H5: ✅ نجح
A6: =COUNTIF($B$2:B6,B6) -> 5 | B6: 1. التشغيل | C6: إعادة التشغيل تعطي نفس النتيجة | D6: شغّلي --yes مرتين، وقارني الرقم الأخير في الشاشة وأرقام report.html | E6: نفس الأرقام تماماً في المرتين (12 / 81 / 37، 13.45) | F6: شاشة cmd + report.html | G6: شُغّل عدة مرات اليوم: نفس 12 / 81 / 37 كل مرة | H6: ✅ نجح
A7: =COUNTIF($B$2:B7,B7) -> 6 | B7: 1. التشغيل | C7: التشغيل من الصفر | D7: انسخي mudrik لمكان آخر، احذفي محتويات data_clean و outputs فقط، ثم شغّلي الأمرين | E7: تُعاد كل الملفات وتطلع نفس الأرقام (12 / 81 / 37) | F7: نسخة المجلد | G7: نسخة نظيفة بلا data_clean ولا outputs (26 أكتوبر): كل الخطوات ok، والجداول مطابقة حرفياً للنسخة السابقة | H7: ✅ نجح
A8: =COUNTIF($B$2:B8,B8) -> 7 | B8: 1. التشغيل | C8: جهاز آخر: Google Colab | D8: افتحي رابط Colab في README ثم Runtime ← Run all | E8: كل فحوص الخلية «٨. فحص إعادة التشغيل» ✅ | F8: Google Colab | G8: 26 أكتوبر: الفحوص الخمسة ✅ (4,328 / 13.45 / 6.87 / 12-81-37 / الملفات الخام لم تتغير) | H8: ✅ نجح
A9: =COUNTIF($B$2:B9,B9) -> 1 | B9: 2. التنظيف | C9: عدد صفوف الجمعيات | D9: افتحي outputs/pipeline_details.log وابحثي عن Non profit Associations | E9: السجلات: 4451 ← 4451 (لا حذف)، الخلايا المعدّلة 1021، للمراجعة 37 | F9: pipeline_details.log | G9: 4451 ← 4451، الخلايا المعدّلة 1021، للمراجعة 37 | H9: ✅ نجح
A10: =COUNTIF($B$2:B10,B10) -> 2 | B10: 2. التنظيف | C10: عدد صفوف المؤسسات | D10: نفس الملف، ابحثي عن Non profit Foundations | E10: السجلات: 386 ← 385 (حُذف صف مكرر واحد فقط)، الخلايا المعدّلة 105 | F10: pipeline_details.log | G10: 386 ← 385 (صف مكرر واحد)، الخلايا المعدّلة 105 | H10: ✅ نجح
A11: =COUNTIF($B$2:B11,B11) -> 3 | B11: 2. التنظيف | C11: لا أعمدة جديدة | D11: افتحي data_clean/Non_profit_Associations_clean.csv (أو ورقة «البيانات المنظفة») | E11: 7 أعمدة فقط بنفس أسماء الملف الأصلي | F11: data_clean | G11: 7 أعمدة بنفس أسماء الملف الأصلي (من صف العناوين) | H11: ✅ نجح
A12: =COUNTIF($B$2:B12,B12) -> 4 | B12: 2. التنظيف | C12: لا تخمين | D12: في ورقة «سجل التعديلات» ابحثي عن «غير محدد» | E12: القيم المجهولة صارت «غير محدد» ومعها السبب، ولا يوجد ملء إحصائي للتصنيف الفرعي | F12: outputs/cleaning/Non profit Associations_cleaned.xlsx | G12: القيم المجهولة أو في مستوى خاطئ صارت «غير محدد» مع نوع المشكلة؛ لا ملء إحصائي | H12: ✅ نجح
A13: =COUNTIF($B$2:B13,B13) -> 5 | B13: 2. التنظيف | C13: كل تعديل مسجل | D13: افتحي ورقة «سجل التعديلات» واختاري 3 صفوف عشوائياً | E13: كل صف فيه: الصف، العمود، القيمة قبل، بعد، السبب | F13: نفس الملف | G13: كل صف: رقم الصف الأصلي، الاسم، العمود، قبل، بعد، نوع المشكلة، طريقة المعالجة | H13: ✅ نجح
... A19: =COUNTIF($B$2:B19,B19) -> 1 | B19: 4. الحساب | C19: المتوسط الوطني بيدك | D19: احسبي: 4,328 ÷ 32,175,224 × 100,000 | E19: 13.45 | F19: آلة حاسبة | G19: 13.45 | H19: ✅ نجح
A20: =COUNTIF($B$2:B20,B20) -> 2 | B20: 4. الحساب | C20: الشرقية بيدك | D20: في outputs/tables/region_summary.xlsx: 352 ÷ 5,125,254 × 100,000 | E20: 6.87، والمؤشر 6.87 ÷ 13.45 = 0.51 | F20: outputs/tables | G20: 6.8679 ≈ 6.87 | H20: ✅ نجح | I20: الفرق 6.86/6.87 تقريب فقط
A21: =COUNTIF($B$2:B21,B21) -> 3 | B21: 4. الحساب | C21: الرياض بيدك | D21: 961 ÷ 8,591,748 × 100,000 | E21: 11.19 | F21: outputs/tables | G21: 11.1852 ≈ 11.19 | H21: ✅ نجح | I21: الفرق تقريب فقط
A22: =COUNTIF($B$2:B22,B22) -> 4 | B22: 4. الحساب | C22: خانة واحدة بيدك | D22: في rate_per100k_region_group.xlsx: الشرقية × الدعوة والتعليم الديني (46 جمعية) | E22: لكل 100 ألف 0.90، المتوسط الوطني 2.50، المؤشر 0.36، الناقص ≈ 2.50 × 51.25 − 46 = 82.2 | F22: outputs/tables | G22: 0.90 / 0.36 / ≈82.1 | H22: ✅ نجح | I22: الجدول 82.2؛ الفرق لأن الكود يستخدم 2.5024 غير مقرّبة
A23: =COUNTIF($B$2:B23,B23) -> 5 | B23: 4. الحساب | C23: المجموع يطابق | D23: اجمعي عمود «عدد الجمعيات» في rate_per100k_region_group.xlsx | E23: 4,328 (= 4,451 − 2 وطنية − 121 غير مصنفة) | F23: outputs/tables + analysis_decisions_log.csv | G23: 4,328 | H23: ✅ نجح
A24: =COUNTIF($B$2:B24,B24) -> 6 | B24: 4. الحساب | C24: المستبعدون موثقون | D24: افتحي outputs/analysis_decisions_log.csv | E24: excluded_national_entities = 2، excluded_unclassified = 121، rows_in_rate = 4328 | F24: outputs | G24: 2 / 121 / 4328 (من 4451) | H24: ✅ نجح | I24: من analysis_decisions_log.xlsx
A25: =COUNTIF($B$2:B25,B25) -> 1 | B25: 5. مصفوفة القرار | C25: أعداد التوصيات | D25: افتحي decision_matrix.xlsx وفلتري عمود «التوصية» | E25: أولوية دعم 12 (منها 5 أرقام قليلة)، تغطية مناسبة 81 (11 أرقام قليلة)، تغطية عالية 37 | F25: outputs/tables | G25: 12 (5 أرقام قليلة) / 81 (11) / 37 (0) | H25: ✅ نجح | I25: من analysis_decisions_log.xlsx
A26: =COUNTIF($B$2:B26,B26) -> 2 | B26: 5. مصفوفة القرار | C26: قاعدة التوصية | D26: اختاري 3 خانات وقارني «المؤشر» بالتوصية | E26: أقل من 0.5 = أولوية دعم، 0.5 إلى أقل من 1.5 = مناسبة، 1.5 فأكثر = عالية | F26: outputs/tables | G26: أولوية دعم: أعلى مؤشر 0.49 | مناسبة: 0.5–1.49 | عالية: أقل مؤشر 1.5 | H26: ✅ نجح | I26: فحصت صفوف أولوية الدعم بنفسي؛ وتحقق Claude من صفوف «تغطية عالية» الـ37 في الملف
A27: =COUNTIF($B$2:B27,B27) -> 3 | B27: 5. مصفوفة القرار | C27: قاعدة «أرقام قليلة» | D27: اختاري خانة فيها جمعية أو اثنتين | E27: مستوى الثقة = «أرقام قليلة» | F27: outputs/tables | G27: الصفوف 9–13: 5 خانات «أرقام قليلة» بلا ترتيب أولوية | H27: ✅ نجح
A28: =COUNTIF($B$2:B28,B28) -> 4 | B28: 5. مصفوفة القرار | C28: تغيير قرار بشري | D28: في scripts/config.json غيّري low_ratio من 0.5 إلى 0.6 ثم شغّلي --yes | E28: أولوية دعم تصير 21 بدل 12 | F28: شاشة cmd | G28: low_ratio 0.6 ← أولوية دعم 21، مناسبة 72، عالية 37 | H28: ✅ نجح
A29: =COUNTIF($B$2:B29,B29) -> 5 | B29: 5. مصفوفة القرار | C29: إرجاع القرار | D29: رجّعي low_ratio إلى 0.5 وشغّلي --yes | E29: ترجع 12 / 81 / 37 بالضبط | F29: شاشة cmd | G29: low_ratio 0.5 ← 12 / 81 / 37 بالضبط | H29: ✅ نجح
A30: =COUNTIF($B$2:B30,B30) -> 1 | B30: 6. عدسة الطلب | C30: ضغط التخصص بيدك | D30: في demand_pressure.xlsx: التعليم والأبحاث 2.379 ÷ 1.546 | E30: 1.54 = ضغط مرتفع | F30: outputs/tables | G30: 2.379 ÷ 1.546 = 1.5388 (الحاسبة قصّت إلى 1.53، والتقريب 1.54) = ضغط مرتفع | H30: ✅ نجح
A31: =COUNTIF($B$2:B31,B31) -> 2 | B31: 6. عدسة الطلب | C31: العدسة لا تغيّر التوصية | D31: قارني التوصيات في decision_matrix قبل وبعد (نفس 12 / 81 / 37) | E31: التوصيات نفسها، فقط عمود «الترتيب بعد عدسة الطلب» جديد | F31: outputs/tables | G31: ما زالت 12 أولوية دعم؛ أُضيفت أعمدة الطلب فقط | H31: ✅ نجح
A32: =COUNTIF($B$2:B32,B32) -> 3 | B32: 6. عدسة الطلب | C32: إعادة الترتيب | D32: في decision_matrix: الشرقية × التعليم والأبحاث | E32: ترتيب الأولوية 5 ← بعد العدسة 2 | F32: outputs/tables | G32: الشرقية × التعليم والأبحاث: 5 ← 2 (ضغط 1.54) | H32: ✅ نجح
A33: =COUNTIF($B$2:B33,B33) -> 4 | B33: 6. عدسة الطلب | C33: المصدر | D33: قارني survey2018_demand_clean.csv بملف Excel المسح (ورقتا المنشآت والمستفيدين) | E33: نفس النسب (التعليم 1.546% و2.379%) | F33: data_clean + data_raw | G33: ملف الهيئة: المنشآت 1.55% (0.015461) والمستفيدين 2.38% (0.023793) = نفس الأرقام | H33: ✅ نجح
A34: =COUNTIF($B$2:B34,B34) -> 1 | B34: 7. فجوة 2030 | C34: الاختبار الرجعي | D34: افتحي outputs/tables/forecast_log.csv | E34: CAGR خطأ 4.39% مقابل خطي 7.75%، والمختار CAGR | F34: outputs/tables | G34: CAGR 4.39 مقابل خطي 7.75، والمختار CAGR (من forecast_log.xlsx) | H34: ✅ نجح | I34: أُضيفت نسخة xlsx للملف لأن csv فتح بعمود واحد
A35: =COUNTIF($B$2:B35,B35) -> 2 | B35: 7. فجوة 2030 | C35: سكان 2030 | D35: نفس الملف | E35: 39,181,053 | F35: outputs/tables | G35: 39181053 | H35: ✅ نجح
A36: =COUNTIF($B$2:B36,B36) -> 3 | B36: 7. فجوة 2030 | C36: الناقص | D36: نفس الملف + forecast_2030_regions.xlsx | E36: 902 اليوم ← 1,592 في 2030؛ الرياض 527.6 والشرقية 511.9 | F36: outputs/tables | G36: 902 ← 1592؛ الرياض 298.7 ← 527.6 والشرقية 337.4 ← 511.9 | H36: ✅ نجح
A37: =COUNTIF($B$2:B37,B37) -> 1 | B37: 8. التقرير | C37: يفتح بدون إنترنت | D37: افصلي الإنترنت وافتحي outputs/report.html | E37: يفتح كاملاً مع الرسوم | F37: outputs/report.html | G37: فُصل الإنترنت وفتح التقرير كاملاً مع الرسوم | H37: ✅ نجح
A38: =COUNTIF($B$2:B38,B38) -> 2 | B38: 8. التقرير | C38: الأرقام الرئيسية | D38: شوفي المربعات أعلى التقرير | E38: 4,328 | 13.45 | 12 (7 بأرقام كافية) | F38: report.html | G38: 4,328 | 13.45 | 12 (7 بأرقام كافية) (تحقق 27 أكتوبر بعد حذف قسم الكفاءة) | H38: ✅ نجح
A39: =COUNTIF($B$2:B39,B39) -> 3 | B39: 8. التقرير | C39: التفاعل | D39: مرّري الماوس على صف منطقة وخانة في المصفوفة | E39: يظهر مربع تفاصيل بالأرقام | F39: report.html | G39: يظهر مربع التفاصيل بالأرقام | H39: ✅ نجح
A40: =COUNTIF($B$2:B40,B40) -> 4 | B40: 8. التقرير | C40: فلتر المصفوفة | D40: اضغطي زر «أولوية دعم» | E40: تبقى 12 خانة واضحة والباقي باهت | F40: report.html | G40: تبقى 12 خانة واضحة والباقي باهت | H40: ✅ نجح
A41: =COUNTIF($B$2:B41,B41) -> 5 | B41: 8. التقرير | C41: المحاكي: خط الأساس | D41: انزلي لقسم المحاكي قبل أي إضافة | E41: «أولوية دعم بأرقام كافية» = 7، والمجموع الناقص 902 | F41: report.html | G41: قبل: 7 بأرقام كافية، و902 ناقص | H41: ✅ نجح
A42: =COUNTIF($B$2:B42,B42) -> 6 | B42: 8. التقرير | C42: المحاكي: إضافة | D42: الشرقية + الدعوة والتعليم الديني + 82 ثم «أضف للسيناريو» | E42: خانتها تتحول من «أولوية دعم»، والعدد 7 ← 6 | F42: report.html | G42: +82 (بالأرقام العربية ٨٢ أيضاً): الخانة صارت تغطية مناسبة، 7 ← 6، الكل 12 ← 11 | H42: ✅ نجح
A43: =COUNTIF($B$2:B43,B43) -> 7 | B43: 8. التقرير | C43: المحاكي: توزيع تلقائي | D43: إعادة ضبط، ثم وزّعي 60 تلقائياً (بدون ترجيح الطلب) | E43: «أولوية دعم بأرقام كافية» = 0 | F43: report.html | G43: 60 جمعية: بأرقام كافية 7 ← 0، الكل 12 ← 5، الناقص 902 ← 882 | H43: ✅ نجح
A44: =COUNTIF($B$2:B44,B44) -> 8 | B44: 8. التقرير | C44: نسخة PDF | D44: افتحي outputs/report.pdf | E44: كل الأقسام ظاهرة بدون قص (المحاكي غير موجود لأنه تفاعلي) | F44: outputs/report.pdf | G44: كل الأقسام ظاهرة بدون قص، والمحاكي غير موجود | H44: ✅ نجح
A45: =COUNTIF($B$2:B45,B45) -> 1 | B45: 9. الوكيل | C45: التوقف بدون موافقة | D45: شغّلي run_pipeline.py بدون --yes | E45: لا يُحسب أي تحليل، ويتوقف عند القرارات | F45: شاشة cmd | G45: توقف عند القرارات بدون أي تحليل | H45: ✅ نجح | I45: نفس اختبار 1-1
...
